Workbook

Sheet Bien ban thuong thao
A1: CÔNG TY TNHH DS CORPORATION | F1: CỘNG HÒA XÃ HỘI CHỦ NGHĨA VIỆT NAM – Độc lập – Tự do – Hạnh phúc
A3: BIÊN BẢN THƯƠNG THẢO HỢP ĐỒNG GIA CÔNG SẢN XUẤT MỸ PHẨM
A4: Sản phẩm: Pre-Shampoo Scalp Oil-Serum 50 ml – LOT công thức 26I261
A6: Số biên bản | B6: 01/2026/BBTT/DS-SHI
A7: Thời gian | B7: …… giờ ……, ngày …… /10/2026
A8: Địa điểm / hình thức | B8: ……………………………… (trực tiếp / trực tuyến)
A9: Cơ sở thương thảo | B9: Dự thảo HĐ số 05/10/2026-HĐMB/SHI-DS CORPORATION/TC-1 do Công ty TNHH Hóa Dược Shizencos gửi ngày 05/10/2026 và Dự thảo sửa đổi của DS Corporation ngày 09/10/2026 (Hợp đồng gia công số 05/10/2026-HĐGC/DS-SHI/TC-1)
A10: Đại diện DS Corporation | B10: 1. Bà Trương Ngọc Ánh – Tổng Giám đốc 2. ……………………………… – ………………
A11: Đại diện Shizencos | B11: 1. Bà Nguyễn Thị Tuyết Vân – Tổng Giám đốc 2. ……………………………… – ………………
A12: Nội dung | B12: Hai bên rà soát từng điều khoản của dự thảo hợp đồng và Phụ lục yêu cầu kỹ thuật (Sheet “Yeu cau ky thuat”). Kết quả từng nội dung ghi tại cột I và J. Các nội dung “Đồng ý” / “Đồng ý có sửa đổi” được đưa vào bản Hợp đồng chính thức.
A13: Quy ước | B13: Bên A = DS Corporation (bên đặt gia công); Bên B = Shizencos (bên nhận gia công) theo dự thảo sửa đổi. Các ô màu vàng nhạt do hai bên điền trong buổi thương thảo.
A15: STT | B15: Điều (dự thảo Shizencos) | C15: Điều (dự thảo DS) | D15: Nội dung dự thảo Shizencos | E15: Đề xuất sửa đổi của DS | F15: Căn cứ / Lý do | G15: Tính chất | H15: Ý kiến Shizencos | I15: Kết quả | J15: Nội dung chốt cuối cùng
A16: 1 | B16: Tiêu đề | C16: Tiêu đề, Điều 2 | D16: “Hợp đồng mua bán (v/v sản xuất và gia công sản phẩm theo yêu cầu)” | E16: Đổi thành “Hợp đồng gia công sản xuất mỹ phẩm” | F16: Bản chất giao dịch là gia công (Luật Thương mại 2005 Điều 178–184; BLDS 2015 Điều 542–553). Hồ sơ công bố mỹ phẩm sản xuất trong nước cần hợp đồng sản xuất/gia công giữa tổ chức công bố và nhà sản xuất | G16: Pháp lý
A17: 2 | B17: Phần chủ thể | C17: Phần chủ thể | D17: Bên A: Shizencos (bên gia công); Bên B: DS (bên thuê gia công) | E17: Bên A: DS (bên đặt gia công); Bên B: Shizencos (bên nhận gia công) | F17: Thống nhất thuật ngữ theo Luật Thương mại (bên đặt gia công/bên nhận gia công); không làm thay đổi bản chất nghĩa vụ của mỗi bên | G17: Pháp lý
A18: 3 | B18: Căn cứ | C18: Căn cứ | D18: BLDS 2015; Luật Thương mại 2005 | E18: Bổ sung: Nghị định 93/2016/NĐ-CP (sửa đổi bởi NĐ 155/2018/NĐ-CP); Thông tư 06/2011/TT-BYT (sửa đổi, bổ sung); Nghị định 43/2017/NĐ-CP (sửa đổi bởi NĐ 111/2021/NĐ-CP) | F18: Các văn bản chuyên ngành điều chỉnh sản xuất, công bố, ghi nhãn mỹ phẩm | G18: Pháp lý
A19: 4 | B19: Điều 1 | C19: Điều 2.1 | D19: Nhãn hàng “DS CORPORATION” | E19: Nhãn hàng: [●] – trùng với tên trên phiếu công bố và bao bì | F19: Tên nhãn hàng trên phiếu công bố phải khớp nhãn sản phẩm lưu hành | G19: Pháp lý
A20: 5 | B20: Điều 1 | C20: Điều 2.3 | D20: Số lượng thực tế dao động ±5–10%, thanh toán theo thực tế | E20: Dung sai ±3%, không vượt số lượng đặt; thiếu hụt do lỗi Bên nhận gia công phải sản xuất bù trong 10 ngày làm việc | F20: Bao bì do DS nhập khẩu theo số lượng cố định; dung sai 10% gây thiếu hàng/thừa chi phí | G20: Thương mại
A21: 6 | B21: Điều 1 | C21: Điều 2.2; Phụ lục 03 | D21: Đơn giá 59.800 đ/hộp trọn gói, không bóc tách | E21: Giữ đơn giá 59.800 đ; bổ sung Phụ lục 03 cấu thành giá (giá dịch/kg, định mức g/chai, công chiết rót – dán nhãn – đóng hộp – co màng – đóng thùng); giá cố định cho đơn hàng và có hiệu lực 06 tháng cho đơn tái đặt | F21: Minh bạch chi phí, làm cơ sở đối chiếu hao hụt và đơn hàng sau | G21: Thương mại
A22: 7 | B22: Điều 1 | C22: Điều 3.1; Phụ lục 01 | D22: Chỉ ghi LOT công thức 26I261, không đính kèm yêu cầu | E22: Phụ lục 01: danh mục 22 thành phần (INCI chuẩn hóa) + khoảng hàm lượng tối thiểu của 08 thành phần chủ chốt + giới hạn an toàn. Shizencos được bảo mật % của các thành phần còn lại | F22: Bảo đảm công dụng tương đương benchmark mà không yêu cầu công khai toàn bộ công thức; không làm thay đổi đơn giá đã báo | G22: Chất lượng
A23: 8 | B23: Điều 1 | C23: Điều 3.3 | D23: Mẫu chốt theo dõi tối thiểu 07–14 ngày | E23: Mẫu chốt có chữ ký hai bên + báo cáo ổn định tăng tốc (40–45 °C) tối thiểu 04 tuần trước sản xuất đại trà, trừ khi DS chấp thuận sản xuất sớm bằng văn bản | F23: Sản phẩm dầu chứa tinh dầu và dầu giàu omega dễ ôi/đổi mùi; 7–14 ngày chưa đủ phát hiện | G23: Chất lượng
A24: 9 | B24: Điều 1 | C24: Điều 3.5 | D24: Biến thiên tự nhiên về màu, mùi giữa các lô không coi là lỗi | E24: Giữ nguyên, nhưng chỉ chấp nhận trong giới hạn Tiêu chuẩn cơ sở (Phụ lục 02); ngoài giới hạn là lỗi sản phẩm | F24: Cần ngưỡng đo được để nghiệm thu | G24: Chất lượng
A25: 10 | B25: Điều 2 | C25: Điều 7 | D25: Thanh toán 70% sau ký; 30% khi Bên gia công thông báo hoàn tất | E25: Đợt 1: 50% trong 05 ngày làm việc sau ký HĐ và nhận đề nghị thanh toán. Đợt 2: 50% trong 07 ngày làm việc sau biên bản nghiệm thu + COA lô + hóa đơn GTGT + biên bản đối chiếu bao bì | F25: Gắn thanh toán với kết quả nghiệm thu chất lượng | G25: Thương mại
A26: 11 | B26: Điều 2 | C26: Điều 7.4 | D26: Lãi chậm trả theo lãi suất nợ quá hạn của Vietcombank | E26: Lãi chậm trả theo Điều 306 Luật Thương mại (lãi suất nợ quá hạn trung bình trên thị trường tại thời điểm thanh toán) | F26: Theo quy định pháp luật, tránh tranh chấp về cách xác định | G26: Pháp lý
A27: 12 | B27: Điều 3 | C27: Điều 4.4 | D27: Hao hụt bao bì 3–10% tùy danh mục | E27: Chai/nắp/dropper ≤ 3%; nhãn/hộp/tem ≤ 2%. Vượt định mức do lỗi Bên nhận gia công thì bồi hoàn theo giá mua; đối chiếu và trả bao bì dư trong 07 ngày làm việc sau sản xuất | F27: Bao bì nhập khẩu, giá cao, lead time dài | G27: Thương mại
... A50: 35 | B50: Điều 10 | C50: Điều 16 | D50: Lập 02 bản, mỗi bên giữ 01 | E50: Lập 04 bản, mỗi bên giữ 02 (01 bản dùng cho hồ sơ công bố) | F50: Hồ sơ công bố cần bản sao hợp đồng | G50: Vận hành
A52: KẾT LUẬN
A53: 1. | B53: ="Số nội dung đã thống nhất: "&(COUNTIF(I16:I50,"Đồng ý")+COUNTIF(I16:I50,"Đồng ý có sửa đổi"))&" / 35; chưa thống nhất: "&COUNTIF(I16:I50,"Chưa thống nhất")
A54: 2. | B54: Yêu cầu kỹ thuật công thức (Sheet “Yeu cau ky thuat”): Shizencos xác nhận công thức 26I261 đáp ứng khoảng hàm lượng thành phần chủ chốt trong đơn giá 59.800 đ/hộp đã báo; nếu cần điều chỉnh làm thay đổi chi phí, Shizencos thông báo chênh lệch bằng văn bản trước khi làm mẫu.
A55: 3. | B55: Các nội dung chưa thống nhất: hai bên phản hồi bằng văn bản/email trước ngày …… /10/2026.
A56: 4. | B56: Shizencos gửi bản Hợp đồng hoàn chỉnh theo kết quả thương thảo; dự kiến ký Hợp đồng ngày …… /…… /2026.
A57: 5. | B57: Biên bản là căn cứ hoàn thiện Hợp đồng, không thay thế Hợp đồng chính thức.
A59: ĐẠI DIỆN DS CORPORATION | F59: ĐẠI DIỆN SHIZENCOS
A60: (Ký, ghi rõ họ tên) | F60: (Ký, ghi rõ họ tên)

Sheet Yeu cau ky thuat
A1: YÊU CẦU KỸ THUẬT CÔNG THỨC – THÀNH PHẦN CHỦ CHỐT (Phụ lục 01 Hợp đồng)
A2: Shizencos được bảo mật tỷ lệ toàn bộ công thức. DS chỉ yêu cầu hàm lượng của 08 thành phần chủ chốt nằm trong khoảng [Tối thiểu – Trần] để bảo đảm công dụng tương đương sản phẩm tham chiếu, cùng các giới hạn an toàn. Yêu cầu không làm thay đổi đơn giá đã báo. Shizencos chỉ cần chọn “Cam kết đạt” hoặc ghi giải trình; không cần ghi % thực tế.
A4: A. THÀNH PHẦN CHỦ CHỐT
A5: STT V3 | B5: Thành phần | C5: INCI | D5: Công dụng định hướng | E5: Tối thiểu (%) | F5: Khuyến nghị (%) | G5: Trần (%) | H5: Căn cứ đối chiếu sản phẩm tham chiếu | I5: Xác nhận Shizencos | J5: Giải trình (nếu có)
A6: 8 | B6: Dầu me rừng (Amla oil) | C6: Phyllanthus Emblica Fruit Extract (+ dầu nền theo COA) | D6: 1. Nuôi dưỡng da đầu – chân tóc | E6: 3,0 | F6: 3,0 – 5,0 | G6: 8,0 | H6: Tham chiếu: Emblica Officinalis Fruit Extract 0,80. Lượng amla thực tế đưa vào phải ≥ mức benchmark (0,8% chiết xuất). “Amla oil” thường là chiết xuất pha loãng trong dầu nền nên cần ≥ 3%; nếu là dạng đậm đặc, Shizencos quy đổi theo COA.
A7: 12 | B7: BAKUCHIOL 99% | C7: Bakuchiol | D7: 1. Nuôi dưỡng da đầu – chống oxy hóa, tái tạo | E7: 0,5 | F7: 0,5 – 0,8 | G7: 1,0 | H7: Tham chiếu: Psoralea Corylifolia Seed Extract 0,20. 0,5% là mức thấp nhất có dữ liệu hiệu quả trên da; benchmark chỉ dùng chiết xuất thô 0,2%. Đây là hoạt chất đắt nhất – mức 0,5% đủ vượt benchmark mà không đẩy giá.
A8: 14 | B8: Tinh dầu hương thảo | C8: Rosmarinus Officinalis (Rosemary) Leaf Oil | D8: 1. Kích thích tuần hoàn, cảm giác da đầu khỏe | E8: 0,5 | F8: 0,8 – 1,0 | G8: 1,5 | H8: Tham chiếu: Rosemary Leaf Extract 0,35. Dạng tinh dầu ≥ 0,5% đã mạnh hơn chiết xuất 0,35% của benchmark; trên 1,5% mùi long não gắt, dễ kích ứng.
A9: 18 | B9: Tinh dầu tràm trà | C9: Melaleuca Alternifolia (Tea Tree) Leaf Oil | D9: 4. Cân bằng vi sinh, giảm bong vảy | E9: 0,5 | F9: 0,5 – 0,8 | G9: 1,0 | H9: Tham chiếu: Basil / Holy Basil / Neem (vai trò tương đương). Dưới 0,5% gần như chỉ còn tác dụng hương; trên 1% tăng nguy cơ kích ứng khi ủ 15–40 phút.
A10: 10 | B10: Dầu Neem | C10: Azadirachta Indica Seed Oil | D10: 4. Làm dịu, cân bằng vi sinh | E10: 0,3 | F10: 0,3 – 0,5 | G10: 0,7 | H10: Tham chiếu: Melia Azadirachta (lá/hoa/extract) tổng 0,58. Tương đương tổng Neem của benchmark; trên 0,7% mùi tỏi–lưu huỳnh lấn át hương.
A11: 11 | B11: Dầu chùm ngây | C11: Moringa Oleifera Seed Oil | D11: 3. Bảo vệ màng lipid trước gội | E11: 0,75 | F11: 1,0 – 2,0 | G11: 3,0 | H11: Tham chiếu: Moringa Oleifera Seed Oil 0,75. Tối thiểu bằng benchmark; dầu bền oxy hóa, giá thấp.
A12: 20 | B12: Bisabolol | C12: Bisabolol | D12: 4. Làm dịu, giảm châm chích của tinh dầu | E12: 0,2 | F12: 0,3 – 0,5 | G12: 1,0 | H12: Tham chiếu: Aloe / Basil (vai trò làm dịu). Cần đủ để trung hòa cảm giác châm chích của hệ tinh dầu.
A13: 22 | B13: Tocopherol 100 | C13: Tocopherol | D13: Bảo vệ hạn dùng (chống ôi dầu) | E13: 0,2 | F13: 0,2 – 0,3 | G13: 0,5 | H13: Tham chiếu: Tocopherol 0,45 + chất chống oxy hóa tổng hợp 0,10. Bắt buộc để hệ dầu giàu omega (Sachi, hạt nho) không ôi trong hạn dùng; trên 0,5% có thể phản tác dụng.
A15: B. GIỚI HẠN AN TOÀN
A16: STT | B16: Thành phần / nhóm | D16: Mục đích | E16: Giới hạn | I16: Xác nhận Shizencos | J16: Giải trình
A17: 1 | B17: Tinh dầu bạc hà – Mentha Piperita Oil | D17: Tránh buốt rát da đầu | E17: ≤ 0,5%
A18: 2 | B18: Tinh dầu gừng – Zingiber Officinale Root Oil | D18: Tránh nóng rát | E18: ≤ 0,3%
A19: 3 | B19: Tinh dầu bưởi – Citrus Maxima/Grandis Peel Oil | D19: Limonene là chất gây mẫn cảm; ưu tiên loại chưng cất/FCF | E19: ≤ 0,8%
A20: 4 | B20: Tổng tinh dầu (hương thảo, bưởi, tràm trà, bạc hà, oải hương, gừng, nghệ) | D20: Giới hạn kích ứng & allergen phải ghi nhãn | E20: ≤ 3,5%
A21: 5 | B21: Nước, dầu khoáng (Mineral Oil/Paraffinum Liquidum), paraben, silicone | D21: Theo định hướng sản phẩm | E21: Không chứa
A23: C. TIÊU CHÍ CẢM QUAN – HIỆU NĂNG (các thành phần nền do Shizencos tự cân đối để đạt)
A24: STT | B24: Tiêu chí | C24: Yêu cầu | I24: Xác nhận Shizencos | J24: Ghi chú
A25: 1 | B25: Dàn trải & cảm giác | C25: Lan tốt, không bết rít; khô bề mặt ≤ 5 phút
A26: 2 | B26: Khả năng gội sạch | C26: Sạch hoàn toàn sau 1–2 lần dầu gội thông thường, không còn màng nhờn
A27: 3 | B27: Châm chích / kích ứng | C27: Điểm châm chích ≤ 2/5 trên panel; không đỏ, ngứa sau ủ 40 phút
A28: 4 | B28: Mùi | C28: Thảo mộc – cam chanh, không lấn mùi Neem; ổn định sau 4 tuần ở 40–45 °C
A29: 5 | B29: Ngoại quan | C29: Dầu trong, vàng nhạt – vàng; không cặn, không tách lớp
A30: 6 | B30: Ổn định | C30: Không ôi, không đổi màu/mùi bất thường sau 4 tuần 40–45 °C, 4 °C và 6 chu kỳ nóng–lạnh; peroxide ≤ 5 meq O₂/kg khi xuất xưởng
A32: D. ĐỀ NGHỊ CHUẨN HÓA INCI TRÊN CÔNG THỨC V3 (24/09/2026)
A33: STT V3 | B33: V3 đang ghi | C33: INCI đề nghị | I33: Xác nhận Shizencos | J33: Ghi chú
A34: 3 | B34: Simmondsia Chinensis Oil | C34: Simmondsia Chinensis (Jojoba) Seed Oil
A35: 4 | B35: Grape Seed Oil | C35: Vitis Vinifera (Grape) Seed Oil
A36: 6 | B36: Argania Spinos Oil | C36: Argania Spinosa Kernel Oil
A37: 8 | B37: Amla Oil | C37: Phyllanthus Emblica Fruit Extract + INCI dầu nền (theo COA)
A38: 13 | B38: Citrus Maxima (Tinh dầu bưởi da xanh) | C38: Citrus Maxima Peel Oil / Citrus Grandis (Grapefruit) Peel Oil (theo COA)
A39: 15 | B39: Zingiber Officinale (Ginger) Root Oil (Ginger Oil ) | C39: Zingiber Officinale (Ginger) Root Oil
A40: 16 | B40: Curcuma Longa (Turmeric Oil) | C40: Curcuma Longa (Turmeric) Root Oil
A41: 19 | B41: Lavandula Angustifolia (Lavender Oil) | C41: Lavandula Angustifolia (Lavender) Oil
A43: E. TÀI LIỆU NGUYÊN LIỆU ĐỀ NGHỊ CUNG CẤP
A44: • COA, MSDS của toàn bộ nguyên liệu (phục vụ PIF).
A45: • Amla oil: nhà sản xuất, dầu nền, nồng độ chiết xuất amla; xác nhận không chứa dầu khoáng.
...

Sheet Tong hop
A1: TỔNG HỢP KẾT QUẢ THƯƠNG THẢO
A3: Tính chất | B3: Tổng số | C3: Đồng ý | D3: Đồng ý có sửa đổi | E3: Chưa thống nhất | F3: Chưa ghi kết quả
A4: Pháp lý | B4: =COUNTIF('Bien ban thuong thao'!$G$16:$G$50,A4) | C4: =COUNTIFS('Bien ban thuong thao'!$G$16:$G$50,A4,'Bien ban thuong thao'!$I$16:$I$50,"Đồng ý") | D4: =COUNTIFS('Bien ban thuong thao'!$G$16:$G$50,A4,'Bien ban thuong thao'!$I$16:$I$50,"Đồng ý có sửa đổi") | E4: =COUNTIFS('Bien ban thuong thao'!$G$16:$G$50,A4,'Bien ban thuong thao'!$I$16:$I$50,"Chưa thống nhất") | F4: =B4-C4-D4-E4
A5: Chất lượng | B5: =COUNTIF('Bien ban thuong thao'!$G$16:$G$50,A5) | C5: =COUNTIFS('Bien ban thuong thao'!$G$16:$G$50,A5,'Bien ban thuong thao'!$I$16:$I$50,"Đồng ý") | D5: =COUNTIFS('Bien ban thuong thao'!$G$16:$G$50,A5,'Bien ban thuong thao'!$I$16:$I$50,"Đồng ý có sửa đổi") | E5: =COUNTIFS('Bien ban thuong thao'!$G$16:$G$50,A5,'Bien ban thuong thao'!$I$16:$I$50,"Chưa thống nhất") | F5: =B5-C5-D5-E5
A6: Thương mại | B6: =COUNTIF('Bien ban thuong thao'!$G$16:$G$50,A6) | C6: =COUNTIFS('Bien ban thuong thao'!$G$16:$G$50,A6,'Bien ban thuong thao'!$I$16:$I$50,"Đồng ý") | D6: =COUNTIFS('Bien ban thuong thao'!$G$16:$G$50,A6,'Bien ban thuong thao'!$I$16:$I$50,"Đồng ý có sửa đổi") | E6: =COUNTIFS('Bien ban thuong thao'!$G$16:$G$50,A6,'Bien ban thuong thao'!$I$16:$I$50,"Chưa thống nhất") | F6: =B6-C6-D6-E6
A7: Vận hành | B7: =COUNTIF('Bien ban thuong thao'!$G$16:$G$50,A7) | C7: =COUNTIFS('Bien ban thuong thao'!$G$16:$G$50,A7,'Bien ban thuong thao'!$I$16:$I$50,"Đồng ý") | D7: =COUNTIFS('Bien ban thuong thao'!$G$16:$G$50,A7,'Bien ban thuong thao'!$I$16:$I$50,"Đồng ý có sửa đổi") | E7: =COUNTIFS('Bien ban thuong thao'!$G$16:$G$50,A7,'Bien ban thuong thao'!$I$16:$I$50,"Chưa thống nhất") | F7: =B7-C7-D7-E7
A8: TỔNG CỘNG | B8: =SUM(B4:B7) | C8: =SUM(C4:C7) | D8: =SUM(D4:D7) | E8: =SUM(E4:E7) | F8: =SUM(F4:F7)
A10: Tỷ lệ đã thống nhất | B10: =IF(B8=0,0,(C8+D8)/B8)
A11: Thành phần chủ chốt đã cam kết | B11: =COUNTIF('Yeu cau ky thuat'!$I$6:$I$13,"Cam kết đạt")&" / 8"
